Workbook

Sheet PLANILLA
A1: ITEM | B1: Nombre | C1: Cedula | D1: Domicilio | E1: CiudadDom | F1: Cargo | G1: RESPONSABILIDADES | H1: DIRTRABAJO | I1: Ciudad | J1: HORARIO1 | K1: HORARIO2 | L1: FECHAINICIO | M1: FECHAFINAL | N1: HABERBASICO | O1: Telefono | P1: CAMISA | Q1: PANTALON | R1: BOTINES | S1: CHALECO | U1: CAMISA | V1: PANTALON | X1: mail | Y1: FACTURA TOTAL
A2: 1 | B2: RAMIRO ARMANDO SUAREZ RIBERO | C2: 2839001 | D2: Urb el Castillo D43 | E2: Cochabamba | F2: Project Manager Central | G2: * Coordinar, monitorear y optimizar la ejecución de proyectos en su región, asegurando el cumplimiento de plazos, indicadores, reportes de gestión y estándares de calidad establecidos. * Elaborar informes de avance, control y desempeño mediante indicadores de gestión. * Diseñar y actualizar tableros de control en Power BI para la visualización y análisis de resultados. * Identificar desviaciones, riesgos y oportunidades de mejora en la ejecución de los proyectos. * Coordinar con equipos multidisciplinarios para asegurar el cumplimiento de objetivos. * Reportar avances, hallazgos y propuestas de mejora a la jefatura o gerencia correspondiente * Planificar, coordinar y asistir en dar seguimiento a los proyectos asignados. * Ejecutar las labores asignadas por el CONTRATANTE sin limitaciones dentro del marco coherente del Cargo. | H2: Parque Industrial Manzano 6 | I2: Santa Cruz | J2: 8:00 a 12:30 14:30 a 18:30 | K2: 9:00 a 12:00 | L2: ´01/4/2026 | M2: 46112 | N2: 9500 | O2: 76444259 | P2: L | Q2: XL/46 | R2: 42 | S2: L | U2: L | V2: XL/46 | X2: rsuarez@redlinegs.com | Y2: 20593.487
A3: 2 | B3: ERICKA YOSELIN FLORES VACA | C3: 9703368 | D3: Barrio El Condado , calle San Juan N.8 | E3: Santa Cruz | F3: Project Manager Regional SCZ | G3: * Coordinar, monitorear y optimizar la ejecución de proyectos en su región, asegurando el cumplimiento de plazos, indicadores, reportes de gestión y estándares de calidad establecidos. * Elaborar informes de avance, control y desempeño mediante indicadores de gestión. * Diseñar y actualizar tableros de control en Power BI para la visualización y análisis de resultados. * Identificar desviaciones, riesgos y oportunidades de mejora en la ejecución de los proyectos. * Coordinar con equipos multidisciplinarios para asegurar el cumplimiento de objetivos. * Reportar avances, hallazgos y propuestas de mejora a la jefatura o gerencia correspondiente * Planificar, coordinar y asistir en dar seguimiento a los proyectos asignados. * Ejecutar las labores asignadas por el CONTRATANTE sin limitaciones dentro del marco coherente del Cargo. | H3: Parque Industrial Manzano 6 | I3: Santa Cruz | J3: 8:00 a 17:00 | K3: 9:00 a 12:00 | L3: ´06/4/2026 | M3: 46112 | N3: 8000 | O3: 78015049 | P3: L | Q3: L/44 | R3: 38 | S3: M | U3: L | V3: L/44 | X3: eflores@redlinegs.com | Y3: 17341.884
A4: 3 | B4: CESAR JOSÉ MOYA VARGAS | C4: 4024225 | D4: Calle Victor Eduardo N. 2391 Miraflores | E4: La Paz | F4: Project Manager Regional LPZ | G4: * Coordinar, monitorear y optimizar la ejecución de proyectos en su región, asegurando el cumplimiento de plazos, indicadores, reportes de gestión y estándares de calidad establecidos. * Elaborar informes de avance, control y desempeño mediante indicadores de gestión. * Diseñar y actualizar tableros de control en Power BI para la visualización y análisis de resultados. * Identificar desviaciones, riesgos y oportunidades de mejora en la ejecución de los proyectos. * Coordinar con equipos multidisciplinarios para asegurar el cumplimiento de objetivos. * Reportar avances, hallazgos y propuestas de mejora a la jefatura o gerencia correspondiente * Planificar, coordinar y asistir en dar seguimiento a los proyectos asignados. * Ejecutar las labores asignadas por el CONTRATANTE sin limitaciones dentro del marco coherente del Cargo. | H4: Av. Panamerica, Extranca Río Seco | I4: El Alto | J4: 8:00 a 17:00 | K4: 9:00 a 12:00 | L4: ´06/4/2026 | M4: 46112 | N4: 8000 | O4: 72471197 | P4: M | Q4: M/42 | S4: M | U4: M | V4: M/42 | X4: cmoya@redlinegs.com | Y4: 17341.884
A5: 4 | B5: OSCAR ROLANDO MENDEZ ROCA FARELL | C5: 4434306 | D5: Urb. Santa Cruz C. Rio Mamore 5370 | E5: Santa Cruz | F5: Project Manager Regional CBA | G5: * Coordinar, monitorear y optimizar la ejecución de proyectos en su región, asegurando el cumplimiento de plazos, indicadores, reportes de gestión y estándares de calidad establecidos. * Elaborar informes de avance, control y desempeño mediante indicadores de gestión. * Diseñar y actualizar tableros de control en Power BI para la visualización y análisis de resultados. * Identificar desviaciones, riesgos y oportunidades de mejora en la ejecución de los proyectos. * Coordinar con equipos multidisciplinarios para asegurar el cumplimiento de objetivos. * Reportar avances, hallazgos y propuestas de mejora a la jefatura o gerencia correspondiente * Planificar, coordinar y asistir en dar seguimiento a los proyectos asignados. * Ejecutar las labores asignadas por el CONTRATANTE sin limitaciones dentro del marco coherente del Cargo. | H5: Av. Blanco Galindo Km10, y Elías Meneses | I5: Cochabamba | J5: 8:00 a 17:00 | K5: 9:00 a 12:00 | L5: ´14/4/2026 | M5: 46112 | N5: 8000 | O5: 75078991 | P5: XL | Q5: XL/46 | R5: 42 | S5: XL | U5: XL | V5: XL/46 | X5: omendez@redlinegs.com | Y5: 17341.884
A6: 5 | B6: JORGE LUIS ROJAS DÁVILA | C6: 5652827 | D6: B. La Morita Monasterio Da Silva N.1A | E6: Santa Cruz | F6: Supervisor Civil Regional SCZ | G6: * Supervisar la correcta ejecución de las obras civiles, verificando que estas se desarrollen conforme a los planos, especificaciones técnicas, normas vigentes y buenas prácticas de ingeniería. * Velar por el estricto cumplimiento de las condiciones contractuales de cada proyecto asignado, incluyendo alcance, plazos, costos, calidad y demás obligaciones establecidas en los contratos suscritos. * Controlar el avance físico de las obras en relación con el cronograma aprobado, identificando desviaciones y gestionando oportunamente las acciones correctivas necesarias. * Asegurar la calidad de los materiales utilizados, así como de los procesos constructivos y resultados finales, conforme a los estándares exigidos. * Verificar el cumplimiento de las normas de seguridad industrial y salud ocupacional en obra, promoviendo condiciones de trabajo seguras y reportando cualquier incumplimiento. * Supervisar el uso eficiente de los recursos asignados (materiales, equipos y mano de obra), evitando desperdicios y optimizando su utilización. * Revisar, validar y dar seguimiento a toda la documentación técnica y administrativa del proyecto, incluyendo informes, planillas de avance, órdenes de cambio, actas y otros documentos relacionados. * Coordinar de manera permanente con contratistas, subcontratistas, proveedores, fiscalización y el cliente, asegurando una adecuada comunicación entre las partes. * Evaluar, gestionar y documentar cualquier modificación, contingencia o imprevisto que surja durante la ejecución del proyecto, conforme a los procedimientos y condiciones contractuales. * Elaborar y presentar informes periódicos sobre el estado de las obras, incluyendo avances, incidencias, cumplimiento contractual y recomendaciones técnicas. * Ejecutar las labores asignadas por el CONTRATANTE sin limitaciones dentro del marco coherente del Cargo. | H6: Parque Industrial Manzano 6 | I6: Santa Cruz | J6: 8:00 a 17:00 | K6: 9:00 a 12:00 | L6: ´01/4/2026 | M6: 46112 | N6: 9165 | O6: 67629591 | P6: S | Q6: S/39 | R6: 39 | S6: S | U6: S | V6: S/39 | X6: jrojas@redlinegs.com | Y6: 19867.296
A7: 6 | B7: MARTIN EDUARDO VELIZ AREVALO | C7: 3556248 | D7: C.Litoral 1261 Miraflores | E7: La Paz | F7: Supervisor Civil Regional LPZ | G7: * Supervisar la correcta ejecución de las obras civiles, verificando que estas se desarrollen conforme a los planos, especificaciones técnicas, normas vigentes y buenas prácticas de ingeniería. * Velar por el estricto cumplimiento de las condiciones contractuales de cada proyecto asignado, incluyendo alcance, plazos, costos, calidad y demás obligaciones establecidas en los contratos suscritos. * Controlar el avance físico de las obras en relación con el cronograma aprobado, identificando desviaciones y gestionando oportunamente las acciones correctivas necesarias. * Asegurar la calidad de los materiales utilizados, así como de los procesos constructivos y resultados finales, conforme a los estándares exigidos. * Verificar el cumplimiento de las normas de seguridad industrial y salud ocupacional en obra, promoviendo condiciones de trabajo seguras y reportando cualquier incumplimiento. * Supervisar el uso eficiente de los recursos asignados (materiales, equipos y mano de obra), evitando desperdicios y optimizando su utilización. * Revisar, validar y dar seguimiento a toda la documentación técnica y administrativa del proyecto, incluyendo informes, planillas de avance, órdenes de cambio, actas y otros documentos relacionados. * Coordinar de manera permanente con contratistas, subcontratistas, proveedores, fiscalización y el cliente, asegurando una adecuada comunicación entre las partes. * Evaluar, gestionar y documentar cualquier modificación, contingencia o imprevisto que surja durante la ejecución del proyecto, conforme a los procedimientos y condiciones contractuales. * Elaborar y presentar informes periódicos sobre el estado de las obras, incluyendo avances, incidencias, cumplimiento contractual y recomendaciones técnicas. * Ejecutar las labores asignadas por el CONTRATANTE sin limitaciones dentro del marco coherente del Cargo. | H7: Av. Panamerica, Extranca Río Seco | I7: El Alto | J7: 8:00 a 17:00 | K7: 9:00 a 12:00 | L7: ´07/4/2026 | M7: 46112 | N7: 8485 | O7: 71249899 | P7: XL | Q7: XL/46 | S7: XL | U7: XL | V7: XL/46 | X7: mveliz@redlinegs.com | Y7: 18393.236
A8: 7 | B8: OSCAR FABIAN QUIROGA TAMAYO | C8: 6500154 | D8: RB Mirador Turupaya | E8: Cochabamba | F8: Supervisor Civil Regional CBA | G8: * Supervisar la correcta ejecución de las obras civiles, verificando que estas se desarrollen conforme a los planos, especificaciones técnicas, normas vigentes y buenas prácticas de ingeniería. * Velar por el estricto cumplimiento de las condiciones contractuales de cada proyecto asignado, incluyendo alcance, plazos, costos, calidad y demás obligaciones establecidas en los contratos suscritos. * Controlar el avance físico de las obras en relación con el cronograma aprobado, identificando desviaciones y gestionando oportunamente las acciones correctivas necesarias. * Asegurar la calidad de los materiales utilizados, así como de los procesos constructivos y resultados finales, conforme a los estándares exigidos. * Verificar el cumplimiento de las normas de seguridad industrial y salud ocupacional en obra, promoviendo condiciones de trabajo seguras y reportando cualquier incumplimiento. * Supervisar el uso eficiente de los recursos asignados (materiales, equipos y mano de obra), evitando desperdicios y optimizando su utilización. * Revisar, validar y dar seguimiento a toda la documentación técnica y administrativa del proyecto, incluyendo informes, planillas de avance, órdenes de cambio, actas y otros documentos relacionados. * Coordinar de manera permanente con contratistas, subcontratistas, proveedores, fiscalización y el cliente, asegurando una adecuada comunicación entre las partes. * Evaluar, gestionar y documentar cualquier modificación, contingencia o imprevisto que surja durante la ejecución del proyecto, conforme a los procedimientos y condiciones contractuales. * Elaborar y presentar informes periódicos sobre el estado de las obras, incluyendo avances, incidencias, cumplimiento contractual y recomendaciones técnicas. * Ejecutar las labores asignadas por el CONTRATANTE sin limitaciones dentro del marco coherente del Cargo. | H8: Av. Blanco Galindo Km10, y Elías Meneses | I8: Cochabamba | J8: 8:00 a 17:00 | K8: 9:00 a 12:00 | L8: ´01/4/2026 | M8: 46112 | N8: 8485 | O8: 67457878 | P8: M | Q8: M/42 | R8: 42 | S8: M | U8: M | V8: M/42 | X8: oquiroga@redlinegs.com | Y8: 18393.236
A9: 8 | B9: RAÚL RAIMUNDO PARRAGA ANTEZANA | C9: 6250669 | D9: B. San Jose Obrero, C. Huacaraje 2260 | E9: Santa Cruz | F9: Supervisor Eléctrico Regional | G9: * Supervisar la ejecución, mantenimiento y operación de los sistemas eléctricos de la planta, verificando su conformidad con planos, especificaciones técnicas, normativas vigentes y buenas prácticas de ingeniería eléctrica. * Velar por el estricto cumplimiento de las condiciones contractuales de los proyectos eléctricos asignados, incluyendo alcance, plazos, calidad, costos, garantías y demás obligaciones establecidas en los contratos suscritos. * Controlar la calidad de las instalaciones eléctricas, asegurando la correcta instalación de equipos, la ejecución de pruebas eléctricas, la puesta en marcha y el funcionamiento seguro de los sistemas. * Garantizar el cumplimiento de las normas de seguridad eléctrica y prevención de riesgos, incluyendo la correcta aplicación de procedimientos de bloqueo y etiquetado (LOTO), uso de equipos de protección personal y control de trabajos energizados. * Coordinar, dirigir y supervisar al personal técnico y contratistas eléctricos, asegurando el cumplimiento de las actividades programadas, la calidad del trabajo y el uso adecuado de recursos. * Elaborar, revisar y dar seguimiento a informes técnicos, reportes de avance, registros de mantenimiento, órdenes de trabajo y demás documentación técnica y contractual, asegurando la trazabilidad de las actividades realizadas. * Ejecutar las labores asignadas por el CONTRATANTE sin limitaciones dentro del marco coherente del Cargo | H9: Parque Industrial Manzano 6 | I9: Santa Cruz | J9: 8:00 a 17:00 | K9: 9:00 a 12:00 | L9: ´01/4/2026 | M9: 46112 | N9: 9165 | O9: 76363514 | P9: L | Q9: L/44 | R9: 41 | S9: L | U9: L | V9: L/44 | X9: rparraga@redlinegs.com | Y9: 19867.296
A10: 9 | B10: ABRAHAM QUENA CABRERA | C10: 8250103 | D10: Av Tres Pasos al frente . C Carmelo Perez SN | E10: Santa Cruz | F10: Supervisor Mecánico Regional | G10: * Supervisar la instalación, mantenimiento y operación de los equipos y sistemas mecánicos de la planta, verificando su conformidad con planos, especificaciones técnicas, normativas vigentes y buenas prácticas de ingeniería. * Velar por el estricto cumplimiento de las condiciones contractuales de los proyectos mecánicos asignados, incluyendo alcance, plazos, calidad, costos, garantías y demás obligaciones establecidas en los contratos suscritos. * Controlar la calidad de los trabajos mecánicos, asegurando la correcta ejecución de actividades como montaje, alineación, ajustes, pruebas de funcionamiento y puesta en marcha de equipos, conforme a estándares técnicos aplicables. * Garantizar el cumplimiento de las normas de seguridad industrial en todas las actividades mecánicas, promoviendo la prevención de riesgos, el uso adecuado de equipos de protección personal y la aplicación de procedimientos seguros de trabajo. * Coordinar, dirigir y supervisar al personal técnico y contratistas mecánicos, asegurando el cumplimiento de las actividades programadas, la calidad del trabajo y el uso eficiente de los recursos asignados. * Elaborar, revisar y dar seguimiento a informes técnicos, reportes de avance, registros de mantenimiento, órdenes de trabajo y demás documentación técnica y contractual, asegurando la trazabilidad de todas las actividades realizadas. * Ejecutar las labores asignadas por el CONTRATANTE sin limitaciones dentro del marco coherente del Cargo. | H10: Parque Industrial Manzano 6 | I10: Santa Cruz | J10: 8:00 a 17:00 | K10: 9:00 a 12:00 | L10: ´01/4/2026 | M10: 46112 | N10: 9165 | O10: 73158361 | P10: L | Q10: M/42 | R10: 42 | S10: L | U10: L | V10: M/42 | X10: aquena@redlinegs.com | Y10: 19867.296
A11: 10 | B11: DAVID ARIEL PEREDO MIRANDA | C11: 6771897 | D11: Irpavi II, Calle 5 N. 20 | E11: La Paz | F11: Supervisor Elt/Mec Regional | G11: * Supervisar la instalación, operación y mantenimiento de los equipos y sistemas electromecánicos de la planta, verificando su conformidad con planos, especificaciones técnicas, normativas vigentes y buenas prácticas de ingeniería. * Velar por el estricto cumplimiento de las condiciones contractuales de los proyectos asignados, incluyendo alcance, plazos, calidad, costos, garantías y demás obligaciones establecidas en los contratos suscritos. * Controlar la calidad de los trabajos electromecánicos, asegurando la correcta ejecución de actividades como montaje de equipos, conexiones eléctricas, alineación, pruebas integrales y puesta en marcha, conforme a estándares técnicos aplicables. * Garantizar el cumplimiento de las normas de seguridad industrial y eléctrica en todas las actividades, incluyendo la correcta aplicación de procedimientos de bloqueo y etiquetado (LOTO), uso de equipos de protección personal y control de trabajos críticos. * Coordinar, dirigir y supervisar al personal técnico y contratistas electromecánicos, asegurando el cumplimiento de las actividades programadas, la calidad del trabajo y el uso eficiente de los recursos asignados. * Elaborar, revisar y dar seguimiento a informes técnicos, reportes de avance, registros de mantenimiento, órdenes de trabajo y demás documentación técnica y contractual, asegurando la trazabilidad de todas las actividades realizadas. * Ejecutar las labores asignadas por el CONTRATANTE sin limitaciones dentro del marco coherente del Cargo. | H11: Av. Panamerica, Extranca Río Seco | I11: El Alto | J11: 8:00 a 17:00 | K11: 9:00 a 12:00 | L11: ´01/4/2026 | M11: 46112 | N11: 16240 | O11: 67199782 | P11: M | Q11: M/42 | R11: 42 | S11: M | U11: M | V11: M/42 | X11: dperedo@redlinegs.com | Y11: 35204.025
A12: 11 | B12: ERIN CALLEJAS VELASQUEZ | C12: 10634775 | D12: Av Virgen de Lujan. B. Bibosi C. 10 | E12: Santa Cruz | F12: Supervisor Elt/Mec Regional | G12: * Supervisar la instalación, operación y mantenimiento de los equipos y sistemas electromecánicos de la planta, verificando su conformidad con planos, especificaciones técnicas, normativas vigentes y buenas prácticas de ingeniería. * Velar por el estricto cumplimiento de las condiciones contractuales de los proyectos asignados, incluyendo alcance, plazos, calidad, costos, garantías y demás obligaciones establecidas en los contratos suscritos. * Controlar la calidad de los trabajos electromecánicos, asegurando la correcta ejecución de actividades como montaje de equipos, conexiones eléctricas, alineación, pruebas integrales y puesta en marcha, conforme a estándares técnicos aplicables. * Garantizar el cumplimiento de las normas de seguridad industrial y eléctrica en todas las actividades, incluyendo la correcta aplicación de procedimientos de bloqueo y etiquetado (LOTO), uso de equipos de protección personal y control de trabajos críticos. * Coordinar, dirigir y supervisar al personal técnico y contratistas electromecánicos, asegurando el cumplimiento de las actividades programadas, la calidad del trabajo y el uso eficiente de los recursos asignados. * Elaborar, revisar y dar seguimiento a informes técnicos, reportes de avance, registros de mantenimiento, órdenes de trabajo y demás documentación técnica y contractual, asegurando la trazabilidad de todas las actividades realizadas. * Ejecutar las labores asignadas por el CONTRATANTE sin limitaciones dentro del marco coherente del Cargo. | H12: Av. Blanco Galindo Km10, y Elías Meneses | I12: Cochabamba | J12: 8:00 a 17:00 | K12: 9:00 a 12:00 | L12: ´01/4/2026 | M12: 46112 | N12: 12483 | O12: 78682540 | P12: L | Q12: M/42 | R12: 42 EUR | S12: L | U12: L | V12: M/42 | X12: ecallejas@redlinegs.com | Y12: 27059.842
A13: 12 | B13: JOSUÉ CONRRADO FERNÁNDEZ SOTEZ | C13: 6835465 | D13: C. Montenegro 1123 Z. Norte | E13: La Paz | F13: Encargado de Almacén | G13: * Administrar, controlar y mantener actualizado el inventario de materiales, equipos y suministros, asegurando su correcta recepción, almacenamiento, conservación y despacho. * Velar por el cumplimiento de las condiciones contractuales relacionadas con el suministro, almacenamiento y entrega de materiales para cada proyecto asignado, incluyendo plazos, cantidades, calidad y especificaciones técnicas. * Supervisar la recepción de materiales y equipos, verificando su conformidad con las órdenes de compra, especificaciones técnicas y documentación correspondiente. * Organizar y garantizar el adecuado almacenamiento de los materiales, asegurando condiciones óptimas de conservación, seguridad, identificación y trazabilidad dentro del almacén. * Coordinar con las áreas de compras, logística, supervisión y ejecución de proyectos, a fin de asegurar el abastecimiento oportuno de materiales conforme a los requerimientos y cronogramas establecidos. * Elaborar, mantener y dar seguimiento a los registros de entradas, salidas, saldos y movimientos de inventario, así como a los informes periódicos y documentación de respaldo correspondiente. * Ejecutar las labores asignadas por el CONTRATANTE sin limitaciones dentro del marco coherente del Cargo. | H13: Av. Panamerica, Extranca Río Seco | I13: El Alto | J13: 8:00 a 17:00 | K13: 9:00 a 12:00 | L13: ´01/4/2026 | M13: 46112 | N13: 3808 | O13: 76259101 | P13: M | Q13: M/42 | R13: 40 | S13: L | U13: M | V13: M/42 | X13: jfernandez@redlinegs.com | Y13: 8254.7368
N14: =SUM(N2:N13) -> 110496

Sheet PL1
D1: CERTIFICADO DE PAGO | AL1: Fecha: | AM1: 46132
AL2: 1
D3: CLIENTE: | E3: EMBOL S.A. / GERENCIA DE OPERACIONES E INNOVACION TECNOLOGICA | W3: PERIODO: | Y3: 46113
D5: SERVICIO: | E5: SERVICIO DE SUPERVISION DE PROYECTOS | W5: DIAS LABORABLES: | AB5: 22
D7: ORDEN DE COMPRA: | W7: MONEDA: | Y7: Bolivianos
AL8: CERTIFICADO
A10: PLANILLA DE PERSONAL
A12: ITEM | B12: NOMBRE | C12: CARGO | D12: FECHA DE INICIO | E12: HABER BASICO | F12: DIAS | AK12: TOTAL DIAS | AL12: HABER GANADO | AM12: FACTURADO
F13: 1 | G13: 2 | H13: 3 | I13: 4 | J13: 5 | K13: 6 | L13: 7 | M13: 8 | N13: 9 | O13: 10 | P13: 11 | Q13: 12 | R13: 13 | S13: 14 | T13: 15 | U13: 16 | V13: 17 | W13: 18 | X13: 19 | Y13: 20 | Z13: 21 | AA13: 22 | AB13: 23 | AC13: 24 | AD13: 25 | AE13: 26 | AF13: 27 | AG13: 28 | AH13: 29 | AI13: 30 | AJ13: 31
A14: 1 | B14: RAMIRO ARMANDO SUAREZ RIBERO | C14: Project Manager Central | D14: 46113 | E14: 9500 | F14: =+IF('1'!F10>1,"SI","NO") -> SI | G14: =+IF('1'!F11>1,"SI","NO") -> SI | H14: =+IF('1'!F12>1,"SI","NO") -> SI | I14: =+IF('1'!F13>1,"SI","NO") -> NO | J14: =+IF('1'!F14>1,"SI","NO") -> NO | K14: =+IF('1'!F15>1,"SI","NO") -> SI | L14: =+IF('1'!F16>1,"SI","NO") -> SI | M14: =+IF('1'!F17>1,"SI","NO") -> SI | N14: =+IF('1'!F18>1,"SI","NO") -> SI | O14: =+IF('1'!F19>1,"SI","NO") -> SI | P14: =+IF('1'!M13>1,"SI","NO") -> NO | Q14: =+IF('1'!M14>1,"SI","NO") -> NO | R14: =+IF('1'!F22>1,"SI","NO") -> SI | S14: =+IF('1'!F23>1,"SI","NO") -> SI | T14: =+IF('1'!F24>1,"SI","NO") -> SI | U14: =+IF('1'!F25>1,"SI","NO") -> SI | V14: =+IF('1'!F26>1,"SI","NO") -> SI | W14: =+IF('1'!F27>1,"SI","NO") -> NO | X14: =+IF('1'!F28>1,"SI","NO") -> NO | Y14: =+IF('1'!F29>1,"SI","NO") -> SI | Z14: =+IF('1'!F30>1,"SI","NO") -> SI | AA14: =+IF('1'!F31>1,"SI","NO") -> SI | AB14: =+IF('1'!F32>1,"SI","NO") -> SI | AC14: =+IF('1'!F33>1,"SI","NO") -> SI | AD14: =+IF('1'!M27>1,"SI","NO") -> NO | AE14: =+IF('1'!M28>1,"SI","NO") -> NO | AF14: =+IF('1'!F36>1,"SI","NO") -> SI | AG14: =+IF('1'!F37>1,"SI","NO") -> SI | AH14: =+IF('1'!F38>1,"SI","NO") -> SI | AI14: =+IF('1'!F39>1,"SI","NO") -> SI | AJ14: =+IF('1'!F41>1,"SI","NO") -> NO | AK14: =+COUNTIF(F14:AJ14,"SI") -> 22 | AL14: =+AK14/$AB$5*E14 -> 9500 | AM14: =+AL14/0.461310893326238 -> 20593.487
A15: 2 | B15: ERICKA YOSELIN FLORES VACA | C15: Project Manager Regional SCZ | D15: 46118 | E15: 8000 | F15: =+IF(#REF!>1,"SI","NO") -> #REF! | G15: =+IF(#REF!>1,"SI","NO") -> #REF! | H15: =+IF(#REF!>1,"SI","NO") -> #REF! | I15: =+IF(#REF!>1,"SI","NO") -> #REF! | J15: =+IF(#REF!>1,"SI","NO") -> #REF! | K15: =+IF(#REF!>1,"SI","NO") -> #REF! | L15: =+IF(#REF!>1,"SI","NO") -> #REF! | M15: =+IF(#REF!>1,"SI","NO") -> #REF! | ... AJ15: =+IF(#REF!>1,"SI","NO") -> #REF! | AK15: =+COUNTIF(F15:AJ15,"SI") -> 0 | AL15: =+AK15/$AB$5*E15 -> 0 | AM15: =+AL15/0.461310893326238 -> 0
A16: 3 | B16: CESAR JOSÉ MOYA VARGAS | C16: Project Manager Regional LPZ | D16: 46118 | E16: 8000 | F16: =+IF(#REF!>1,"SI","NO") -> #REF! | G16: =+IF(#REF!>1,"SI","NO") -> #REF! | H16: =+IF(#REF!>1,"SI","NO") -> #REF! | I16: =+IF(#REF!>1,"SI","NO") -> #REF! | J16: =+IF(#REF!>1,"SI","NO") -> #REF! | K16: =+IF(#REF!>1,"SI","NO") -> #REF! | L16: =+IF(#REF!>1,"SI","NO") -> #REF! | M16: =+IF(#REF!>1,"SI","NO") -> #REF! | ... AJ16: =+IF(#REF!>1,"SI","NO") -> #REF! | AK16: =+COUNTIF(F16:AJ16,"SI") -> 0 | AL16: =+AK16/$AB$5*E16 -> 0 | AM16: =+AL16/0.461310893326238 -> 0
A17: 4 | B17: OSCAR ROLANDO MENDEZ ROCA FARELL | C17: Project Manager Regional CBA | D17: 46126 | E17: 8000 | F17: =+IF(#REF!>1,"SI","NO") -> #REF! | G17: =+IF(#REF!>1,"SI","NO") -> #REF! | H17: =+IF(#REF!>1,"SI","NO") -> #REF! | I17: =+IF(#REF!>1,"SI","NO") -> #REF! | J17: =+IF(#REF!>1,"SI","NO") -> #REF! | K17: =+IF(#REF!>1,"SI","NO") -> #REF! | L17: =+IF(#REF!>1,"SI","NO") -> #REF! | M17: =+IF(#REF!>1,"SI","NO") -> #REF! | ... AJ17: =+IF(#REF!>1,"SI","NO") -> #REF! | AK17: =+COUNTIF(F17:AJ17,"SI") -> 0 | AL17: =+AK17/$AB$5*E17 -> 0 | AM17: =+AL17/0.461310893326238 -> 0
A18: 5 | B18: JORGE LUIS ROJAS DÁVILA | C18: Supervisor Civil Regional SCZ | D18: 46113 | E18: 9165 | F18: =+IF(#REF!>1,"SI","NO") -> #REF! | G18: =+IF(#REF!>1,"SI","NO") -> #REF! | H18: =+IF(#REF!>1,"SI","NO") -> #REF! | I18: =+IF(#REF!>1,"SI","NO") -> #REF! | J18: =+IF(#REF!>1,"SI","NO") -> #REF! | K18: =+IF(#REF!>1,"SI","NO") -> #REF! | L18: =+IF(#REF!>1,"SI","NO") -> #REF! | M18: =+IF(#REF!>1,"SI","NO") -> #REF! | ... AJ18: =+IF(#REF!>1,"SI","NO") -> #REF! | AK18: =+COUNTIF(F18:AJ18,"SI") -> 0 | AL18: =+AK18/$AB$5*E18 -> 0 | AM18: =+AL18/0.461310893326238 -> 0
A19: 6 | B19: MARTIN EDUARDO VELIZ AREVALO | C19: Supervisor Civil Regional LPZ | D19: 46119 | E19: 8485 | F19: =+IF(#REF!>1,"SI","NO") -> #REF! | G19: =+IF(#REF!>1,"SI","NO") -> #REF! | H19: =+IF(#REF!>1,"SI","NO") -> #REF! | I19: =+IF(#REF!>1,"SI","NO") -> #REF! | J19: =+IF(#REF!>1,"SI","NO") -> #REF! | K19: =+IF(#REF!>1,"SI","NO") -> #REF! | L19: =+IF(#REF!>1,"SI","NO") -> #REF! | M19: =+IF(#REF!>1,"SI","NO") -> #REF! | ... AJ19: =+IF(#REF!>1,"SI","NO") -> #REF! | AK19: =+COUNTIF(F19:AJ19,"SI") -> 0 | AL19: =+AK19/$AB$5*E19 -> 0 | AM19: =+AL19/0.461310893326238 -> 0
A20: 7 | B20: OSCAR FABIAN QUIROGA TAMAYO | C20: Supervisor Civil Regional CBA | D20: 46113 | E20: 8485 | F20: =+IF(#REF!>1,"SI","NO") -> #REF! | G20: =+IF(#REF!>1,"SI","NO") -> #REF! | H20: =+IF(#REF!>1,"SI","NO") -> #REF! | I20: =+IF(#REF!>1,"SI","NO") -> #REF! | J20: =+IF(#REF!>1,"SI","NO") -> #REF! | K20: =+IF(#REF!>1,"SI","NO") -> #REF! | L20: =+IF(#REF!>1,"SI","NO") -> #REF! | M20: =+IF(#REF!>1,"SI","NO") -> #REF! | ... AJ20: =+IF(#REF!>1,"SI","NO") -> #REF! | AK20: =+COUNTIF(F20:AJ20,"SI") -> 0 | AL20: =+AK20/$AB$5*E20 -> 0 | AM20: =+AL20/0.461310893326238 -> 0
A21: 8 | B21: RAÚL RAIMUNDO PARRAGA ANTEZANA | C21: Supervisor Eléctrico Regional | D21: 46113 | E21: 9165 | F21: =+IF(#REF!>1,"SI","NO") -> #REF! | G21: =+IF(#REF!>1,"SI","NO") -> #REF! | H21: =+IF(#REF!>1,"SI","NO") -> #REF! | I21: =+IF(#REF!>1,"SI","NO") -> #REF! | J21: =+IF(#REF!>1,"SI","NO") -> #REF! | K21: =+IF(#REF!>1,"SI","NO") -> #REF! | L21: =+IF(#REF!>1,"SI","NO") -> #REF! | M21: =+IF(#REF!>1,"SI","NO") -> #REF! | ... AJ21: =+IF(#REF!>1,"SI","NO") -> #REF! | AK21: =+COUNTIF(F21:AJ21,"SI") -> 0 | AL21: =+AK21/$AB$5*E21 -> 0 | AM21: =+AL21/0.461310893326238 -> 0
A22: 9 | B22: ABRAHAM QUENA CABRERA | C22: Supervisor Mecánico Regional | D22: 46113 | E22: 9165 | F22: =+IF(#REF!>1,"SI","NO") -> #REF! | G22: =+IF(#REF!>1,"SI","NO") -> #REF! | H22: =+IF(#REF!>1,"SI","NO") -> #REF! | I22: =+IF(#REF!>1,"SI","NO") -> #REF! | J22: =+IF(#REF!>1,"SI","NO") -> #REF! | K22: =+IF(#REF!>1,"SI","NO") -> #REF! | L22: =+IF(#REF!>1,"SI","NO") -> #REF! | M22: =+IF(#REF!>1,"SI","NO") -> #REF! | ... AJ22: =+IF(#REF!>1,"SI","NO") -> #REF! | AK22: =+COUNTIF(F22:AJ22,"SI") -> 0 | AL22: =+AK22/$AB$5*E22 -> 0 | AM22: =+AL22/0.461310893326238 -> 0
A23: 10 | B23: DAVID ARIEL PEREDO MIRANDA | C23: Supervisor Elt/Mec Regional | D23: 46113 | E23: 16240 | F23: =+IF(#REF!>1,"SI","NO") -> #REF! | G23: =+IF(#REF!>1,"SI","NO") -> #REF! | H23: =+IF(#REF!>1,"SI","NO") -> #REF! | I23: =+IF(#REF!>1,"SI","NO") -> #REF! | J23: =+IF(#REF!>1,"SI","NO") -> #REF! | K23: =+IF(#REF!>1,"SI","NO") -> #REF! | L23: =+IF(#REF!>1,"SI","NO") -> #REF! | M23: =+IF(#REF!>1,"SI","NO") -> #REF! | ... AJ23: =+IF(#REF!>1,"SI","NO") -> #REF! | AK23: =+COUNTIF(F23:AJ23,"SI") -> 0 | AL23: =+AK23/$AB$5*E23 -> 0 | AM23: =+AL23/0.461310893326238 -> 0
A24: 11 | B24: ERIN CALLEJAS VELASQUEZ | C24: Supervisor Elt/Mec Regional | D24: 46113 | E24: 12483 | F24: =+IF(#REF!>1,"SI","NO") -> #REF! | G24: =+IF(#REF!>1,"SI","NO") -> #REF! | H24: =+IF(#REF!>1,"SI","NO") -> #REF! | I24: =+IF(#REF!>1,"SI","NO") -> #REF! | J24: =+IF(#REF!>1,"SI","NO") -> #REF! | K24: =+IF(#REF!>1,"SI","NO") -> #REF! | L24: =+IF(#REF!>1,"SI","NO") -> #REF! | M24: =+IF(#REF!>1,"SI","NO") -> #REF! | ... AJ24: =+IF(#REF!>1,"SI","NO") -> #REF! | AK24: =+COUNTIF(F24:AJ24,"SI") -> 0 | AL24: =+AK24/$AB$5*E24 -> 0 | AM24: =+AL24/0.461310893326238 -> 0
A25: 12 | B25: JOSUÉ CONRRADO FERNÁNDEZ SOTEZ | C25: Encargado de Almacén | D25: 46113 | E25: 3808 | F25: =+IF(#REF!>1,"SI","NO") -> #REF! | G25: =+IF(#REF!>1,"SI","NO") -> #REF! | H25: =+IF(#REF!>1,"SI","NO") -> #REF! | I25: =+IF(#REF!>1,"SI","NO") -> #REF! | J25: =+IF(#REF!>1,"SI","NO") -> #REF! | K25: =+IF(#REF!>1,"SI","NO") -> #REF! | L25: =+IF(#REF!>1,"SI","NO") -> #REF! | M25: =+IF(#REF!>1,"SI","NO") -> #REF! | ... AJ25: =+IF(#REF!>1,"SI","NO") -> #REF! | AK25: =+COUNTIF(F25:AJ25,"SI") -> 0 | AL25: =+AK25/$AB$5*E25 -> 0 | AM25: =+AL25/0.461310893326238 -> 0
AM26: =SUM(AM14:AM25) -> 20593.487
A28: PASAJES Y VIATICOS | U28: ALQUILER EQUIPOS DE COMPUTACION
A30: ITEM | B30: NOMBRE | C30: DESCRIPCION | D30: FECHA IDA | E30: FECHA REGRESO | F30: DIAS | H30: P.U. (Variable) | K30: CANTIDAD | N30: COSTO TOTAL | P30: FACTURADO | U30: ITEM | W30: DESCRIPCION | AJ30: CANTIDAD | AL30: COSTO TOTAL | AM30: FACTURADO
A32: 1 | C32: Scz-Lpz-Scz | H32: =852*2 -> 1704 | N32: =+K32*H32 -> 0 | P32: =+N32*1.25 -> 0 | U32: 1 | W32: Dotación de Equipos de Computación i5/i7 de ÚLTIMA GENERACIÓN con Licencia Software Basico - Contrato anual. | AJ32: 11 | AL32: 785 | AM32: =+AL32*AJ32 -> 8635
A33: 2 | B33: RAÚL RAIMUNDO PARRAGA ANTEZANA | C33: Scz-Cba-Scz | D33: 46134 | E33: 46135 | H33: =1021*2 -> 2042 | K33: 1 | N33: =+K33*H33 -> 2042 | P33: =+N33*1.25 -> 2552.5 | U33: 2 | W33: Dotación de Equipos de Computación i5/i7 de ÚLTIMA GENERACIÓN con Licencia Software Especializado de diseño - Contrato anual. | AJ33: 0 | AL33: 4857.5 | AM33: =+AL33*AJ33 -> 0
A34: 3 | C34: Scz-Tja-Scz | H34: =851*2 -> 1702 | N34: =+K34*H34 -> 0 | P34: =+N34*1.25 -> 0 | AM34: =SUM(AM32:AM33) -> 8635
A35: 4 | C35: Lpz-Cba-Lpz | H35: =443*2 -> 886 | N35: =+K35*H35 -> 0 | P35: =+N35*1.25 -> 0
A36: 5 | C36: Alojamiento y Alimentación | D36: 46134 | E36: 46135 | F36: 1 | H36: 350 | N36: =+F36*H36 -> 350 | P36: =+N36*1.25 -> 437.5
P37: =SUM(P32:S36) -> 2990
A39: PLANILLA DE ALIMENTACION LA PAZ | AL39: Fee Cont | AM39: 1.16
A41: ITEM | B41: NOMBRE | C41: CARGO | D41: FECHA DE INICIO | E41: P.U. CATERING | F41: DIAS | AK41: TOTAL DIAS | AL41: COSTO TOTAL | AM41: FACTURADO
F42: 1 | G42: 2 | H42: 3 | I42: 4 | J42: 5 | K42: 6 | L42: 7 | M42: 8 | N42: 9 | O42: 10 | P42: 11 | Q42: 12 | R42: 13 | S42: 14 | T42: 15 | U42: 16 | V42: 17 | W42: 18 | X42: 19 | Y42: 20 | Z42: 21 | AA42: 22 | AB42: 23 | AC42: 24 | AD42: 25 | AE42: 26 | AF42: 27 | AG42: 28 | AH42: 29 | AI42: 30 | AJ42: 31
A43: 3 | B43: CESAR JOSÉ MOYA VARGAS | C43: Project Manager Regional LPZ | D43: 46118 | E43: 25 | F43: NO | G43: NO | H43: NO | I43: NO | J43: NO | K43: NO | L43: SI | M43: SI | N43: SI | O43: SI | P43: NO | Q43: NO | R43: SI | S43: SI | T43: SI | U43: SI | V43: SI | W43: NO | X43: NO | Y43: SI | Z43: SI | AA43: SI | AB43: SI | AC43: SI | AD43: NO | AE43: NO | AF43: SI | AG43: SI | AH43: SI | AI43: SI | AJ43: NO | AK43: =+COUNTIF(F43:AJ43,"SI") -> 18 | AL43: =+AK43*E43 -> 450 | AM43: =+AL43*$AM$39 -> 522
A44: 6 | B44: MARTIN EDUARDO VELIZ AREVALO | C44: Supervisor Civil Regional LPZ | D44: 46119 | E44: 25 | F44: NO | G44: NO | H44: NO | I44: NO | J44: NO | K44: NO | L44: SI | M44: SI | N44: SI | O44: SI | P44: NO | Q44: NO | R44: SI | S44: SI | T44: SI | U44: SI | V44: SI | W44: NO | X44: NO | Y44: SI | Z44: SI | AA44: SI | AB44: SI | AC44: SI | AD44: NO | AE44: NO | AF44: SI | AG44: SI | AH44: SI | AI44: SI | AJ44: NO | AK44: =+COUNTIF(F44:AJ44,"SI") -> 18 | AL44: =+AK44*E44 -> 450 | AM44: =+AL44*$AM$39 -> 522
A45: 10 | B45: DAVID ARIEL PEREDO MIRANDA | C45: Supervisor Elt/Mec Regional | D45: 46113 | E45: 25 | F45: SI | G45: SI | H45: SI | I45: NO | J45: NO | K45: SI | L45: SI | M45: SI | N45: SI | O45: SI | P45: NO | Q45: NO | R45: SI | S45: SI | T45: SI | U45: SI | V45: SI | W45: NO | X45: NO | Y45: SI | Z45: SI | AA45: SI | AB45: SI | AC45: SI | AD45: NO | AE45: NO | AF45: SI | AG45: SI | AH45: SI | AI45: SI | AJ45: NO | AK45: =+COUNTIF(F45:AJ45,"SI") -> 22 | AL45: =+AK45*E45 -> 550 | AM45: =+AL45*$AM$39 -> 638
A46: 12 | B46: JOSUÉ CONRRADO FERNÁNDEZ SOTEZ | C46: Encargado de Almacén | D46: 46113 | E46: 25 | F46: SI | G46: SI | H46: SI | I46: NO | J46: NO | K46: SI | L46: SI | M46: SI | N46: SI | O46: SI | P46: NO | Q46: NO | R46: SI | S46: SI | T46: SI | U46: SI | V46: SI | W46: NO | X46: NO | Y46: SI | Z46: SI | AA46: SI | AB46: SI | AC46: SI | AD46: NO | AE46: NO | AF46: SI | AG46: SI | AH46: SI | AI46: SI | AJ46: NO | AK46: =+COUNTIF(F46:AJ46,"SI") -> 22 | AL46: =+AK46*E46 -> 550 | AM46: =+AL46*$AM$39 -> 638
AM47: =SUM(AM43:AM46) -> 2320
A48: PLANILLA DE ALIMENTACION CBA | AL48: Fee Cont | AM48: 1.16
A50: ITEM | B50: NOMBRE | C50: CARGO | D50: FECHA DE INICIO | E50: P.U. CATERING | F50: DIAS | AK50: TOTAL DIAS | AL50: COSTO TOTAL | AM50: FACTURADO
...

Sheet 1
A2: PLANILLA CONTROL DE ASISTENCIA
A4: ITEM | B4: 1
A5: NOMBRE | B5: =+VLOOKUP(B4,PLANILLA!A2:S13,2,FALSE) -> RAMIRO ARMANDO SUAREZ RIBERO
A6: CARGO | B6: =+VLOOKUP(B4,PLANILLA!A2:S13,6,FALSE) -> Project Manager Central
A7: HABER BASICO | B7: =+VLOOKUP(B4,PLANILLA!A2:S13,14,FALSE) -> 9500
A9: FECHA | B9: DIA | C9: HORA INGRESO | D9: HORA SALIDA | E9: REFRIGERIO | F9: HORAS TRABAJO | G9: ATRASOS MINUTOS | H9: OBSERVACIONES
A10: 46113 | B10: =+A10 -> 46113 | C10: 0.33333333 | D10: 0.79166667 | E10: 1 | F10: =+(D10-C10)*24-E10 -> 10 | G10: =+IF(C10>0.333333333333333,+(C10-0.333333333333333)*24*60,"0") -> 0
A11: 46114 | B11: =+A11 -> 46114 | C11: 0.33333333 | D11: 0.79166667 | E11: 1 | F11: =+(D11-C11)*24-E11 -> 10 | G11: =+IF(C11>0.333333333333333,+(C11-0.333333333333333)*24*60,"0") -> 0
A12: 46115 | B12: =+A12 -> 46115 | C12: 0.33333333 | D12: 0.79166667 | E12: 1 | F12: =+(D12-C12)*24-E12 -> 10 | G12: =+IF(C12>0.333333333333333,+(C12-0.333333333333333)*24*60,"0") -> 0
A13: 46116 | B13: =+A13 -> 46116 | F13: =+(D13-C13)*24-E13 -> 0 | G13: =+IF(C13>0.333333333333333,+(C13-0.333333333333333)*24*60,"0") -> 0
A14: 46117 | B14: =+A14 -> 46117 | F14: =+(D14-C14)*24-E14 -> 0 | G14: =+IF(C14>0.333333333333333,+(C14-0.333333333333333)*24*60,"0") -> 0
A15: 46118 | B15: =+A15 -> 46118 | C15: 0.33333333 | D15: 0.79166667 | E15: 1 | F15: =+(D15-C15)*24-E15 -> 10 | G15: =+IF(C15>0.333333333333333,+(C15-0.333333333333333)*24*60,"0") -> 0
A16: 46119 | B16: =+A16 -> 46119 | C16: 0.33333333 | D16: 0.79166667 | E16: 1 | F16: =+(D16-C16)*24-E16 -> 10 | G16: =+IF(C16>0.333333333333333,+(C16-0.333333333333333)*24*60,"0") -> 0
A17: 46120 | B17: =+A17 -> 46120 | C17: 0.33333333 | D17: 0.79166667 | E17: 1 | F17: =+(D17-C17)*24-E17 -> 10 | G17: =+IF(C17>0.333333333333333,+(C17-0.333333333333333)*24*60,"0") -> 0
A18: 46121 | B18: =+A18 -> 46121 | C18: 0.33333333 | D18: 0.79166667 | E18: 1 | F18: =+(D18-C18)*24-E18 -> 10 | G18: =+IF(C18>0.333333333333333,+(C18-0.333333333333333)*24*60,"0") -> 0
A19: 46122 | B19: =+A19 -> 46122 | C19: 0.33333333 | D19: 0.79166667 | E19: 1 | F19: =+(D19-C19)*24-E19 -> 10 | G19: =+IF(C19>0.333333333333333,+(C19-0.333333333333333)*24*60,"0") -> 0
A20: 46123 | B20: =+A20 -> 46123 | F20: =+(D20-C20)*24-E20 -> 0 | G20: =+IF(C20>0.333333333333333,+(C20-0.333333333333333)*24*60,"0") -> 0
A21: 46124 | B21: =+A21 -> 46124 | F21: =+(D21-C21)*24-E21 -> 0 | G21: =+IF(C21>0.333333333333333,+(C21-0.333333333333333)*24*60,"0") -> 0
A22: 46125 | B22: =+A22 -> 46125 | C22: 0.33333333 | D22: 0.79166667 | E22: 1 | F22: =+(D22-C22)*24-E22 -> 10 | G22: =+IF(C22>0.333333333333333,+(C22-0.333333333333333)*24*60,"0") -> 0
A23: 46126 | B23: =+A23 -> 46126 | C23: 0.33333333 | D23: 0.79166667 | E23: 1 | F23: =+(D23-C23)*24-E23 -> 10 | G23: =+IF(C23>0.333333333333333,+(C23-0.333333333333333)*24*60,"0") -> 0
A24: 46127 | B24: =+A24 -> 46127 | C24: 0.33333333 | D24: 0.79166667 | E24: 1 | F24: =+(D24-C24)*24-E24 -> 10 | G24: =+IF(C24>0.333333333333333,+(C24-0.333333333333333)*24*60,"0") -> 0
A25: 46128 | B25: =+A25 -> 46128 | C25: 0.33333333 | D25: 0.79166667 | E25: 1 | F25: =+(D25-C25)*24-E25 -> 10 | G25: =+IF(C25>0.333333333333333,+(C25-0.333333333333333)*24*60,"0") -> 0
A26: 46129 | B26: =+A26 -> 46129 | C26: 0.33333333 | D26: 0.79166667 | E26: 1 | F26: =+(D26-C26)*24-E26 -> 10 | G26: =+IF(C26>0.333333333333333,+(C26-0.333333333333333)*24*60,"0") -> 0
A27: 46130 | B27: =+A27 -> 46130 | F27: =+(D27-C27)*24-E27 -> 0 | G27: =+IF(C27>0.333333333333333,+(C27-0.333333333333333)*24*60,"0") -> 0
A28: 46131 | B28: =+A28 -> 46131 | F28: =+(D28-C28)*24-E28 -> 0 | G28: =+IF(C28>0.333333333333333,+(C28-0.333333333333333)*24*60,"0") -> 0
A29: 46132 | B29: =+A29 -> 46132 | C29: 0.33333333 | D29: 0.79166667 | E29: 1 | F29: =+(D29-C29)*24-E29 -> 10 | G29: =+IF(C29>0.333333333333333,+(C29-0.333333333333333)*24*60,"0") -> 0
A30: 46133 | B30: =+A30 -> 46133 | C30: 0.33333333 | D30: 0.79166667 | E30: 1 | F30: =+(D30-C30)*24-E30 -> 10 | G30: =+IF(C30>0.333333333333333,+(C30-0.333333333333333)*24*60,"0") -> 0
A31: 46134 | B31: =+A31 -> 46134 | C31: 0.33333333 | D31: 0.79166667 | E31: 1 | F31: =+(D31-C31)*24-E31 -> 10 | G31: =+IF(C31>0.333333333333333,+(C31-0.333333333333333)*24*60,"0") -> 0
A32: 46135 | B32: =+A32 -> 46135 | C32: 0.33333333 | D32: 0.79166667 | E32: 1 | F32: =+(D32-C32)*24-E32 -> 10 | G32: =+IF(C32>0.333333333333333,+(C32-0.333333333333333)*24*60,"0") -> 0
A33: 46136 | B33: =+A33 -> 46136 | C33: 0.33333333 | D33: 0.79166667 | E33: 1 | F33: =+(D33-C33)*24-E33 -> 10 | G33: =+IF(C33>0.333333333333333,+(C33-0.333333333333333)*24*60,"0") -> 0
A34: 46137 | B34: =+A34 -> 46137 | F34: =+(D34-C34)*24-E34 -> 0 | G34: =+IF(C34>0.333333333333333,+(C34-0.333333333333333)*24*60,"0") -> 0
A35: 46138 | B35: =+A35 -> 46138 | F35: =+(D35-C35)*24-E35 -> 0 | G35: =+IF(C35>0.333333333333333,+(C35-0.333333333333333)*24*60,"0") -> 0
A36: 46139 | B36: =+A36 -> 46139 | C36: 0.33333333 | D36: 0.79166667 | E36: 1 | F36: =+(D36-C36)*24-E36 -> 10 | G36: =+IF(C36>0.333333333333333,+(C36-0.333333333333333)*24*60,"0") -> 0
A37: 46140 | B37: =+A37 -> 46140 | C37: 0.33333333 | D37: 0.79166667 | E37: 1 | F37: =+(D37-C37)*24-E37 -> 10 | G37: =+IF(C37>0.333333333333333,+(C37-0.333333333333333)*24*60,"0") -> 0
A38: 46141 | B38: =+A38 -> 46141 | C38: 0.33333333 | D38: 0.79166667 | E38: 1 | F38: =+(D38-C38)*24-E38 -> 10 | G38: =+IF(C38>0.333333333333333,+(C38-0.333333333333333)*24*60,"0") -> 0
A39: 46142 | B39: =+A39 -> 46142 | C39: 0.33333333 | D39: 0.79166667 | E39: 1 | F39: =+(D39-C39)*24-E39 -> 10 | G39: =+IF(C39>0.333333333333333,+(C39-0.333333333333333)*24*60,"0") -> 0
A41: TOTAL DIAS TRABAJADOS | C41: =+COUNT(C10:C39) -> 22
A42: TOTAL HORAS TRABAJADAS | C42: =SUM(F10:F39) -> 220
A43: ATRASOS | C43: =SUM(G10:G39) -> 0
